[ERROR][2025-05-22 19:47:51][root] [TRADER ERROR] 'Close'
Traceback (most recent call last):
  File "C:\Users\twtko\AppData\Local\Programs\Python\Python310\lib\site-packages\pandas\core\indexes\base.py", line 3802, in get_loc
    return self._engine.get_loc(casted_key)
  File "pandas\_libs\index.pyx", line 138, in pandas._libs.index.IndexEngine.get_loc
  File "pandas\_libs\index.pyx", line 165, in pandas._libs.index.IndexEngine.get_loc
  File "pandas\_libs\hashtable_class_helper.pxi", line 5745, in pandas._libs.hashtable.PyObjectHashTable.get_item
  File "pandas\_libs\hashtable_class_helper.pxi", line 5753, in pandas._libs.hashtable.PyObjectHashTable.get_item
KeyError: 'Close'

The above exception was the direct cause of the following exception:

Traceback (most recent call last):
  File "C:\Users\twtko\Desktop\UPBIT_AutoTrader_HS\bot\trader.py", line 128, in run_loop
    df = calc_indicators(df)
  File "C:\Users\twtko\Desktop\UPBIT_AutoTrader_HS\bot\indicators.py", line 12, in calc_indicators
    return compute_indicators(df)
  File "C:\Users\twtko\Desktop\UPBIT_AutoTrader_HS\bot\indicators.py", line 32, in compute_indicators
    df['EMA5'] = df['Close'].ewm(span=5, adjust=False).mean()
  File "C:\Users\twtko\AppData\Local\Programs\Python\Python310\lib\site-packages\pandas\core\frame.py", line 3807, in __getitem__
    indexer = self.columns.get_loc(key)
  File "C:\Users\twtko\AppData\Local\Programs\Python\Python310\lib\site-packages\pandas\core\indexes\base.py", line 3804, in get_loc
    raise KeyError(key) from err
KeyError: 'Close'
[ERROR][2025-05-22 19:48:02][root] [TRADER ERROR] 'Close'
Traceback (most recent call last):
  File "C:\Users\twtko\AppData\Local\Programs\Python\Python310\lib\site-packages\pandas\core\indexes\base.py", line 3802, in get_loc
    return self._engine.get_loc(casted_key)
  File "pandas\_libs\index.pyx", line 138, in pandas._libs.index.IndexEngine.get_loc
  File "pandas\_libs\index.pyx", line 165, in pandas._libs.index.IndexEngine.get_loc
  File "pandas\_libs\hashtable_class_helper.pxi", line 5745, in pandas._libs.hashtable.PyObjectHashTable.get_item
  File "pandas\_libs\hashtable_class_helper.pxi", line 5753, in pandas._libs.hashtable.PyObjectHashTable.get_item
KeyError: 'Close'

The above exception was the direct cause of the following exception:

Traceback (most recent call last):
  File "C:\Users\twtko\Desktop\UPBIT_AutoTrader_HS\bot\trader.py", line 128, in run_loop
    df = calc_indicators(df)
  File "C:\Users\twtko\Desktop\UPBIT_AutoTrader_HS\bot\indicators.py", line 12, in calc_indicators
    return compute_indicators(df)
  File "C:\Users\twtko\Desktop\UPBIT_AutoTrader_HS\bot\indicators.py", line 32, in compute_indicators
    df['EMA5'] = df['Close'].ewm(span=5, adjust=False).mean()
  File "C:\Users\twtko\AppData\Local\Programs\Python\Python310\lib\site-packages\pandas\core\frame.py", line 3807, in __getitem__
    indexer = self.columns.get_loc(key)
  File "C:\Users\twtko\AppData\Local\Programs\Python\Python310\lib\site-packages\pandas\core\indexes\base.py", line 3804, in get_loc
    raise KeyError(key) from err
KeyError: 'Close'
